Workbook

Sheet Asset overview
A1: Asset Overview
A2: Asset | B2: Operator | C2: Owner | D2: Country | E2: Region | F2: Port | G2: Current Status
A3: BHP WAIO (5 Hubs) | B3: BHP | C3: BHP 85% / ITOCHU 8% / Mitsui 7% (JV) | D3: Australia | E3: Pilbara | F3: Port Hedland | G3: Operating
A4: Rio Tinto Pilbara (8 Hubs) | B4: Rio Tinto | C4: Rio (HD - Hancock 50%; RV + WA - Mitsui 33% / Nippon 14%; WR - Baowu 46%) | D4: Australia | E4: Pilbara | F4: Dampier + Cape Lambert | G4: Operating
A5: Fortescue Hematite (3 Hubs) | B5: Fortescue | C5: Fortescue 100% | D5: Australia | E5: Pilbara | F5: Port Hedland | G5: Operating
A6: Fortescue Iron Bridge Magnetite Project (1 Hub) | B6: Fortescue | C6: Fortescue 69% / Formosa 31% | D6: Australia | E6: Pilbara | F6: Port Hedland | G6: Operating
A7: Vale Northern System (3 Hubs) | B7: Vale | C7: Vale 100% | D7: Brazil | E7: Pará | F7: Ponta da Madeira | G7: Operating
A8: Vale Southeastern System (3 Hubs) | B8: Vale | C8: Vale 100% | D8: Brazil | E8: Minas Gerais | F8: Tubarão | G8: Operating
A9: Vale Southern System (2 Hubs) | B9: Vale | C9: Vale 100% | D9: Brazil | E9: Minas Gerais | F9: Guaíba + Itaguaí | G9: Operating
A10: Hancock Roy Hill (1 Hub) | B10: Hancock Prospecting | C10: Hancock 70% / Marubeni 15% / POSCO 12.5% / CSC 2.5% | D10: Australia | E10: Pilbara | F10: Port Hedland | G10: Operating
A11: MinRes Onslow Iron (1 Hub) | B11: Mineral Resources | C11: MinRes 60.3% / Baowu 18.7% / AMCI 10.7% / POSCO 10.3% | D11: Australia | E11: West Pilbara | F11: Port of Ashburton | G11: Operating
A12: MinRes Pilbara Hub (1 Hub) | B12: Mineral Resources | C12: MinRes 100% | D12: Australia | E12: Pilbara | F12: Port Hedland | G12: Operating
A13: Hancock Atlas Iron (3 Hubs) | B13: Hancock Prospecting | C13: Hancock 100% | D13: Australia | E13: Pilbara | F13: Port Hedland | G13: Operating
... A72: Sydvaranger (1 Hub) | B72: Grangex | C72: Grangex 100% | D72: Norway | E72: Kirkenes | F72: Kirkenes | G72: Development

Sheet Assumptions
A1: Assumptions by Asset (Representative Shipped Product, Fines Prioritised Where Applicable)
A2: Asset | C2: Grade (%) | D2: Moisture (%) | E2: Royalties (%) | F2: 62% Realisation (%) | G2: 61% Realisation (%) | H2: Baltic Freight Multiplier
A3: BHP WAIO (5 Hubs) | C3: 61 | D3: 7 | E3: 7.5 | F3: =C3/62 -> 0.98387097 | G3: =C3/62 -> 0.98387097 | H3: 1
A4: Rio Tinto Pilbara (8 Hubs) | C4: 60.8 | D4: 7 | E4: 7.5 | F4: =C4/62 -> 0.98064516 | G4: =C4/62 -> 0.98064516 | H4: 1
A5: Fortescue Hematite (3 Hubs) | C5: 58.2 | D5: 8.5 | E5: 7.5 | F5: =C5/62 -> 0.93870968 | G5: =C5/62 -> 0.93870968 | H5: 1
A6: Fortescue Iron Bridge Magnetite Project (1 Hub) | C6: 67 | D6: 9 | E6: 5 | F6: =C6/62 -> 1.0806452 | G6: =C6/62 -> 1.0806452 | H6: 1
A7: Vale Northern System (3 Hubs) | C7: 65 | D7: 8 | E7: 3 | F7: =C7/62 -> 1.0483871 | G7: =C7/62 -> 1.0483871 | H7: 1.06
A8: Vale Southeastern System (3 Hubs) | C8: 61 | D8: 8 | E8: 3 | F8: =C8/62 -> 0.98387097 | G8: =C8/62 -> 0.98387097 | H8: 1
A9: Vale Southern System (2 Hubs) | C9: 60 | D9: 8.5 | E9: 3 | F9: =C9/62 -> 0.96774194 | G9: =C9/62 -> 0.96774194 | H9: 1.01
A10: Hancock Roy Hill (1 Hub) | C10: 60.7 | D10: 8 | E10: 7.5 | F10: =C10/62 -> 0.97903226 | G10: =C10/62 -> 0.97903226 | H10: 1
A11: MinRes Onslow Iron (1 Hub) | C11: 58.2 | D11: 8 | E11: 7.5 | F11: =C11/62 -> 0.93870968 | G11: =C11/62 -> 0.93870968 | H11: 1.03
A12: MinRes Pilbara Hub (1 Hub) | C12: 57.5 | D12: 8.6 | E12: 7.5 | F12: =C12/62 -> 0.92741935 | G12: =C12/62 -> 0.92741935 | H12: 1
A13: Hancock Atlas Iron (3 Hubs) | C13: 58 | D13: 9 | E13: 7.5 | F13: =C13/62 -> 0.93548387 | G13: =C13/62 -> 0.93548387 | H13: 1
A14: CITIC Sino Iron (1 Hub) | C14: 65 | D14: 8 | E14: 5 | F14: =C14/62 -> 1.0483871 | G14: =C14/62 -> 1.0483871 | H14: 1
... A73: Opaque Producer Supply | C73: 60.5 | D73: 8 | E73: 0.8 | F73: =C73/62 -> 0.97580645 | G73: =C73/62 -> 0.97580645 | H73: 1
A74: Total seaborne Supply

Sheet Seaborne Supply
A1: Seaborne Supply by Asset wmt
A2: Asset | C2: 2010 | D2: 2011 | E2: 2012 | F2: 2013 | G2: 2014 | H2: 2015 | I2: 2016 | J2: 2017 | K2: 2018 | L2: 2019 | M2: 2020 | N2: 2021 | O2: 2022 | P2: 2023 | Q2: 2024 | R2: 2025 | S2: 2026 | T2: 2027 | U2: 2028 | V2: 2029 | W2: 2030 | X2: 2031 | Y2: 2032 | Z2: 2033 | AA2: 2034 | AB2: 2035
A3: BHP WAIO (5 Hubs) | C3: 125 | D3: 134.4 | E3: 159.5 | F3: 189.4 | G3: 223.4 | H3: 254 | I3: 257 | J3: 268 | K3: 275 | L3: 270 | M3: 285 | N3: 284 | O3: 284 | P3: 285 | Q3: 287 | R3: 290 | S3: 290 | T3: 292 | U3: 294 | V3: 296 | W3: 297 | X3: 298 | Y3: 298 | Z3: 298 | AA3: 297 | AB3: 296
A4: Rio Tinto Pilbara (8 Hubs) | C4: 222.7 | D4: 225.4 | E4: 239.4 | F4: 250.5 | G4: 280.6 | H4: 309.9 | I4: 327.6 | J4: 330.1 | K4: 338.2 | L4: 327.4 | M4: 330.6 | N4: 321.6 | O4: 321.6 | P4: 331.8 | Q4: 328.6 | R4: 326.2 | S4: 329 | T4: 331 | U4: 332 | V4: 333 | W4: 333 | X4: 333 | Y4: 332 | Z4: 331 | AA4: 330 | AB4: 329
A5: Fortescue Hematite (3 Hubs) | C5: 40 | D5: 40.9 | E5: 57.5 | F5: 80.9 | G5: 124.2 | H5: 165.4 | I5: 169.4 | J5: 170.4 | K5: 170 | L5: 167.7 | M5: 178.2 | N5: 182.2 | O5: 188.7 | P5: 191.8 | Q5: 186.7 | R5: 191.3 | S5: 192 | T5: 191 | U5: 190 | V5: 190 | W5: 190 | X5: 189 | Y5: 188 | Z5: 187 | AA5: 186 | AB5: 185
A6: Fortescue Iron Bridge Magnetite Project (1 Hub) | C6: 0 | D6: 0 | E6: 0 | F6: 0 | G6: 0 | H6: 0 | I6: 0 | J6: 0 | K6: 0 | L6: 0 | M6: 0 | N6: 0 | O6: 0 | P6: 0.2 | Q6: 4.9 | R6: 7.1 | S6: 11 | T6: 12 | U6: 13 | V6: 14 | W6: 15 | X6: 16 | Y6: 16 | Z6: 16 | AA6: 16 | AB6: 16
A7: Vale Northern System (3 Hubs) | C7: 94.2 | D7: 100.5 | E7: 105.4 | F7: 107 | G7: 112.3 | H7: 124.7 | I7: 149 | J7: 169.5 | K7: 198 | L7: 190 | M7: 191.2 | N7: 182.9 | O7: 167.9 | P7: 166.1 | Q7: 175.8 | R7: 172.4 | S7: 170 | T7: 178 | U7: 184 | V7: 188 | W7: 190 | X7: 190 | Y7: 190 | Z7: 190 | AA7: 190 | AB7: 190
A8: Vale Southeastern System (3 Hubs) | C8: 100.4 | D8: 102.9 | E8: 102.6 | F8: 101.6 | G8: 101.5 | H8: 105.4 | I8: 100.7 | J8: 102.2 | K8: 96.8 | L8: 69.2 | M8: 48.8 | N8: 57.6 | O8: 61.5 | P8: 69.2 | Q8: 71.9 | R8: 80.9 | S8: 90 | T8: 92 | U8: 92 | V8: 91 | W8: 90 | X8: 90 | Y8: 89 | Z8: 89 | AA8: 88 | AB8: 88
A9: Vale Southern System (2 Hubs) | C9: 60.5 | D9: 59.1 | E9: 62.6 | F9: 61.8 | G9: 64.4 | H9: 69.3 | I9: 67.5 | J9: 62.6 | K9: 60.4 | L9: 26.7 | M9: 38.8 | N9: 42.8 | O9: 44.1 | P9: 44.7 | Q9: 47.7 | R9: 48 | S9: 46.5 | T9: 53 | U9: 57 | V9: 59 | W9: 60 | X9: 60 | Y9: 60 | Z9: 60 | AA9: 60 | AB9: 60
A10: Hancock Roy Hill (1 Hub) | C10: 0 | D10: 0 | E10: 0 | F10: 0 | G10: 0 | H10: 0 | I10: 14 | J10: 31 | K10: 50 | L10: 55 | M10: 58 | N10: 60 | O10: 60 | P10: 61 | Q10: 63 | R10: 63 | S10: 63 | T10: 62.1 | U10: 61.2 | V10: 59.5 | W10: 56 | X10: 52.5 | Y10: 49 | Z10: 45.5 | AA10: 42 | AB10: 39.4
A11: MinRes Onslow Iron (1 Hub) | C11: 0 | D11: 0 | E11: 0 | F11: 0 | G11: 0 | H11: 0 | I11: 0 | J11: 0 | K11: 0 | L11: 0 | M11: 0 | N11: 0 | O11: 0 | P11: 0 | Q11: 0.2 | R11: 8 | S11: 19.7 | T11: 35 | U11: 35 | V11: 35 | W11: 35 | X11: 35 | Y11: 35 | Z11: 35 | AA11: 35 | AB11: 35
A12: MinRes Pilbara Hub (1 Hub) | C12: 0 | D12: 0 | E12: 0 | F12: 0 | G12: 0 | H12: 6 | I12: 7 | J12: 8 | K12: 8 | L12: 8 | M12: 8 | N12: 9 | O12: 9 | P12: 9 | Q12: 9 | R12: 10 | S12: 10 | T12: 10 | U12: 10 | V12: 10 | W12: 10 | X12: 0 | Y12: 0 | Z12: 0 | AA12: 0 | AB12: 0
A13: Hancock Atlas Iron (3 Hubs) | C13: 6 | D13: 6.5 | E13: 7.5 | F13: 9.5 | G13: 12.2 | H13: 14 | I13: 14.5 | J13: 9 | K13: 9 | L13: 8 | M13: 8 | N13: 9 | O13: 9 | P13: 9 | Q13: 9 | R13: 9 | S13: 9 | T13: 8.9 | U13: 8.8 | V13: 8.5 | W13: 8 | X13: 7.5 | Y13: 7 | Z13: 6.5 | AA13: 6 | AB13: 5.6
... A25: Metinvest Iron Ore (3 Hubs) | C25: 6.1 | D25: 7.3 | E25: 6.5 | F25: 8.2 | G25: 10.9 | H25: 10 | I25: 5.7 | J25: 3.7 | K25: 2 | L25: 4.1 | M25: 7.9 | N25: 4.4 | O25: 2.4 | P25: 2 | Q25: 11.5 | R25: 11.2 | S25: 7.5 | T25: 9 | U25: 10.5 | V25: 11 | W25: 11.5 | X25: 11.7 | Y25: 12 | Z25: 12 | AA25: 12 | AB25: 12
A26: Vedanta (2 Hubs) | C26: =16+3.7+3.4+4 -> 27.1 | D26: 18 | E26: 15.5 | F26: 2.2 | G26: 0 | H26: 0 | I26: 2.3 | J26: 7.3 | K26: 3.3 | L26: 1.3 | M26: 0.9 | N26: 2.1 | O26: 1.1 | P26: 2.2 | Q26: 4.8 | R26: 2.2 | S26: 3 | T26: 3.7 | U26: 3.7 | V26: 5.1 | W26: 5.5 | X26: 5.5 | Y26: 5.5 | Z26: 5.5 | AA26: 5.5 | AB26: 5.5
A27: NMDC (2 Hubs) | C27: 3.7 | D27: 2.6 | E27: 0.4 | F27: 1.6 | G27: 2.3 | H27: 2.5 | I27: 1.1 | J27: 2.7 | K27: 2.6 | L27: 1.2 | M27: 2.4 | N27: 2.3 | O27: 0 | P27: 0 | Q27: 0 | R27: 0.5 | S27: 1.4 | T27: 1.8 | U27: 2 | V27: 2 | W27: 2 | X27: 2 | Y27: 2 | Z27: 2 | AA27: 2 | AB27: 2
A28: Rungta Mines (1 Hub) | C28: 3.4 | D28: 3.5 | E28: 2 | F28: 1.5 | G28: 2.5 | H28: 0.5 | I28: 0 | J28: 2.5 | K28: 2.3 | L28: 4.1 | M28: 6 | N28: 10.5 | O28: 4 | P28: 3.6 | Q28: 9.8 | R28: 9.7 | S28: 9.5 | T28: 9 | U28: 8.5 | V28: 8 | W28: 7.5 | X28: 7 | Y28: 6.5 | Z28: 6.5 | AA28: 6.5 | AB28: 6.5
A29: Gol-e-Gohar (1 Hub) | C29: 3.3 | D29: 1.5 | E29: 1.5 | F29: 0.5 | G29: 2.2 | H29: 0.8 | I29: 1.5 | J29: 1.7 | K29: 1.5 | L29: 1.3 | M29: 0 | N29: 0.4 | O29: 1.6 | P29: 1.1 | Q29: 2 | R29: 0.9 | S29: 0.5 | T29: 0.8 | U29: 0.8 | V29: 0.8 | W29: 0.8 | X29: 0.8 | Y29: 0.8 | Z29: 0.8 | AA29: 0.8 | AB29: 0.8
A30: Goharzamin (1 Hub) | C30: 0 | D30: 0 | E30: 0 | F30: 0 | G30: 0 | H30: 0 | I30: 0.2 | J30: 0.7 | K30: 1.5 | L30: 1.3 | M30: 0.4 | N30: 0.4 | O30: 1.7 | P30: 1.2 | Q30: 1.8 | R30: 1.8 | S30: 0.6 | T30: 0.8 | U30: 0.8 | V30: 0.7 | W30: 0.6 | X30: 0.5 | Y30: 0.5 | Z30: 0.5 | AA30: 0.5 | AB30: 0.8
A31: Chadormalu (1 Hub) | C31: 0.8 | D31: 0.8 | E31: 2 | F31: 0.6 | G31: 0.4 | H31: 0.5 | I31: 0.5 | J31: 0.5 | K31: 0.2 | L31: 0.1 | M31: 0 | N31: 0 | O31: 0 | P31: 0 | Q31: 0 | R31: 0 | S31: 0 | T31: 0.1 | U31: 0.1 | V31: 0.1 | W31: 0.1 | X31: 0.1 | Y31: 0.1 | Z31: 0.1 | AA31: 0.1 | AB31: 0.1
A32: Sangan Iron Ore (1 Hub) | C32: 1 | D32: 1 | E32: 0.9 | F32: 0.8 | G32: 0.6 | H32: 0.3 | I32: 0.4 | J32: 0.4 | K32: 0.2 | L32: 0.1 | M32: 0 | N32: 0 | O32: 0 | P32: 0 | Q32: 0 | R32: 0 | S32: 0 | T32: 0 | U32: 0 | V32: 0 | W32: 0 | X32: 0 | Y32: 0 | Z32: 0 | AA32: 0 | AB32: 0
A33: Iran Central Iron Ore (1 Hub) | C33: 1.4 | D33: 1.4 | E33: 1.5 | F33: 1.8 | G33: 1.5 | H33: 0.8 | I33: 0.8 | J33: 0.7 | K33: 0.4 | L33: 0.2 | M33: 0.1 | N33: 0.1 | O33: 0.1 | P33: 0.1 | Q33: 0.1 | R33: 0.1 | S33: 0 | T33: 0.1 | U33: 0.1 | V33: 0.1 | W33: 0.1 | X33: 0.1 | Y33: 0.1 | Z33: 0.1 | AA33: 0.1 | AB33: 0.1
A34: Sirjan Iranian Steel (1 Hub) | C34: 0 | D34: 0 | E34: 0 | F34: 0 | G34: 0 | H34: 0 | I34: 0 | J34: 0 | K34: 0.1 | L34: 0.1 | M34: 0 | N34: 0.1 | O34: 0.1 | P34: 0.1 | Q34: 0.3 | R34: 0.6 | S34: 0.1 | T34: 0.3 | U34: 0.4 | V34: 0.4 | W34: 0.4 | X34: 0.4 | Y34: 0.4 | Z34: 0.4 | AA34: 0.4 | AB34: 0.4
A35: Opal Parsian Sangan (1 Hub) | C35: 0 | D35: 0 | E35: 0 | F35: 0 | G35: 0 | H35: 0 | I35: 0 | J35: 0 | K35: 0 | L35: 0 | M35: 0 | N35: 0 | O35: 0 | P35: 0.1 | Q35: 0.1 | R35: 0.3 | S35: 0.1 | T35: 0.2 | U35: 0.3 | V35: 0.3 | W35: 0.3 | X35: 0.3 | Y35: 0.3 | Z35: 0.3 | AA35: 0.3 | AB35: 0.3
A36: Marampa (1 Hub) | C36: 0 | D36: 0 | E36: 1.3 | F36: 3.7 | G36: 2.7 | H36: 0 | I36: 0 | J36: 0 | K36: 0 | L36: 0.2 | M36: 0 | N36: 1 | O36: 2.1 | P36: 2.9 | Q36: 2 | R36: 2.8 | S36: 3.4 | T36: 3.7 | U36: 4 | V36: 4.3 | W36: 4.5 | X36: 4.7 | Y36: 5 | Z36: 5 | AA36: 5 | AB36: 5
A37: Tonkolili (1 Hub) | C37: 0 | D37: 1.3 | E37: 4.1 | F37: 12.1 | G37: 15.7 | H37: 0.8 | I37: 4.1 | J37: 6 | K37: 0 | L37: 0 | M37: 0 | N37: 2 | O37: 6.3 | P37: 7.6 | Q37: 9 | R37: 9 | S37: 10 | T37: 10 | U37: 10 | V37: 10 | W37: 10 | X37: 10 | Y37: 10 | Z37: 10 | AA37: 10 | AB37: 10
A38: Simandou WCS Blocks 1&2 (1 Hub) | C38: 0 | D38: 0 | E38: 0 | F38: 0 | G38: 0 | H38: 0 | I38: 0 | J38: 0 | K38: 0 | L38: 0 | M38: 0 | N38: 0 | O38: 0 | P38: 0 | Q38: 0 | R38: 0.2 | S38: 10 | T38: 25 | U38: 50 | V38: 60 | W38: 60 | X38: 60 | Y38: 60 | Z38: 60 | AA38: 60 | AB38: 60
... A72: Sydvaranger (1 Hub) | C72: 1.4 | D72: 1.5 | E72: 1.8 | F72: 2 | G72: 2.2 | H72: 1.8 | I72: 0 | J72: 0 | K72: 0 | L72: 0 | M72: 0 | N72: 0 | O72: 0 | P72: 0 | Q72: 0 | R72: 0 | S72: 0 | T72: 0.5 | U72: 2 | V72: 2.5 | W72: 2.5 | X72: 3 | Y72: 3.3 | Z72: 3.3 | AA72: 3.3 | AB72: 3.3
A73: Opaque Producer Supply | C73: =C74-SUM(C3:C72) -> 204.9 | D73: =D74-SUM(D3:D72) -> 215.6 | E73: =E74-SUM(E3:E72) -> 203.3 | F73: =F74-SUM(F3:F72) -> 239 | G73: =G74-SUM(G3:G72) -> 235.1 | H73: =H74-SUM(H3:H72) -> 147.2 | I73: =I74-SUM(I3:I72) -> 173.2 | J73: =J74-SUM(J3:J72) -> 176.8 | ... AB73: =AB74-SUM(AB3:AB72) -> 81.5
A74: Total seaborne Supply | C74: 1123.6 | D74: 1148.3 | E74: 1214 | F74: 1344 | G74: 1488.5 | H74: 1512 | I74: 1591.6 | J74: 1646.3 | K74: 1667.3 | L74: 1603.9 | M74: 1656.2 | N74: 1659.4 | O74: 1586.8 | P74: 1712 | Q74: 1740.5 | R74: 1761 | S74: 1789 | T74: 1844 | U74: 1891 | V74: 1931 | W74: 1950 | X74: 1965 | Y74: 1975 | Z74: 1985 | AA74: 1985 | AB74: 1980

Sheet Benchmark-equivalent supply
A1: Supply Restated in Benchmark-Grade
A2: Columns up to 2025 are adjusted to the 62% iron benchmark; Columns from 2026 onward are adjusted to the 61%
A3: Fe Benchmark | C3: 0.62 | D3: 0.62 | E3: 0.62 | F3: 0.62 | G3: 0.62 | H3: 0.62 | I3: 0.62 | J3: 0.62 | K3: 0.62 | L3: 0.62 | M3: 0.62 | N3: 0.62 | O3: 0.62 | P3: 0.62 | Q3: 0.62 | R3: 0.62 | S3: 0.61 | T3: 0.61 | U3: 0.61 | V3: 0.61 | W3: 0.61 | X3: 0.61 | Y3: 0.61 | Z3: 0.61 | AA3: 0.61 | AB3: 0.61
A4: Asset | C4: 2010 | D4: 2011 | E4: 2012 | F4: 2013 | G4: 2014 | H4: 2015 | I4: 2016 | J4: 2017 | K4: 2018 | L4: 2019 | M4: 2020 | N4: 2021 | O4: 2022 | P4: 2023 | Q4: 2024 | R4: 2025 | S4: 2026 | T4: 2027 | U4: 2028 | V4: 2029 | W4: 2030 | X4: 2031 | Y4: 2032 | Z4: 2033 | AA4: 2034 | AB4: 2035
A5: BHP WAIO (5 Hubs) | C5: ='Seaborne Supply'!C3*(1-Assumptions!$D3/100)*(Assumptions!$C3/100/'Benchmark-equivalent supply'!C$3) -> 114.375 | D5: ='Seaborne Supply'!D3*(1-Assumptions!$D3/100)*(Assumptions!$C3/100/'Benchmark-equivalent supply'!D$3) -> 122.976 | E5: ='Seaborne Supply'!E3*(1-Assumptions!$D3/100)*(Assumptions!$C3/100/'Benchmark-equivalent supply'!E$3) -> 145.9425 | F5: ='Seaborne Supply'!F3*(1-Assumptions!$D3/100)*(Assumptions!$C3/100/'Benchmark-equivalent supply'!F$3) -> 173.301 | G5: ='Seaborne Supply'!G3*(1-Assumptions!$D3/100)*(Assumptions!$C3/100/'Benchmark-equivalent supply'!G$3) -> 204.411 | H5: ='Seaborne Supply'!H3*(1-Assumptions!$D3/100)*(Assumptions!$C3/100/'Benchmark-equivalent supply'!H$3) -> 232.41 | I5: ='Seaborne Supply'!I3*(1-Assumptions!$D3/100)*(Assumptions!$C3/100/'Benchmark-equivalent supply'!I$3) -> 235.155 | J5: ='Seaborne Supply'!J3*(1-Assumptions!$D3/100)*(Assumptions!$C3/100/'Benchmark-equivalent supply'!J$3) -> 245.22 | ... AB5: ='Seaborne Supply'!AB3*(1-Assumptions!$D3/100)*(Assumptions!$C3/100/'Benchmark-equivalent supply'!AB$3) -> 275.28
A6: Rio Tinto Pilbara (8 Hubs) | C6: ='Seaborne Supply'!C4*(1-Assumptions!$D4/100)*(Assumptions!$C4/100/'Benchmark-equivalent supply'!C$3) -> 203.1024 | D6: ='Seaborne Supply'!D4*(1-Assumptions!$D4/100)*(Assumptions!$C4/100/'Benchmark-equivalent supply'!D$3) -> 205.5648 | E6: ='Seaborne Supply'!E4*(1-Assumptions!$D4/100)*(Assumptions!$C4/100/'Benchmark-equivalent supply'!E$3) -> 218.3328 | F6: ='Seaborne Supply'!F4*(1-Assumptions!$D4/100)*(Assumptions!$C4/100/'Benchmark-equivalent supply'!F$3) -> 228.456 | G6: ='Seaborne Supply'!G4*(1-Assumptions!$D4/100)*(Assumptions!$C4/100/'Benchmark-equivalent supply'!G$3) -> 255.9072 | H6: ='Seaborne Supply'!H4*(1-Assumptions!$D4/100)*(Assumptions!$C4/100/'Benchmark-equivalent supply'!H$3) -> 282.6288 | I6: ='Seaborne Supply'!I4*(1-Assumptions!$D4/100)*(Assumptions!$C4/100/'Benchmark-equivalent supply'!I$3) -> 298.7712 | J6: ='Seaborne Supply'!J4*(1-Assumptions!$D4/100)*(Assumptions!$C4/100/'Benchmark-equivalent supply'!J$3) -> 301.0512 | ... AB6: ='Seaborne Supply'!AB4*(1-Assumptions!$D4/100)*(Assumptions!$C4/100/'Benchmark-equivalent supply'!AB$3) -> 304.96682
A7: Fortescue Hematite (3 Hubs) | C7: ='Seaborne Supply'!C5*(1-Assumptions!$D5/100)*(Assumptions!$C5/100/'Benchmark-equivalent supply'!C$3) -> 34.356774 | D7: ='Seaborne Supply'!D5*(1-Assumptions!$D5/100)*(Assumptions!$C5/100/'Benchmark-equivalent supply'!D$3) -> 35.129802 | E7: ='Seaborne Supply'!E5*(1-Assumptions!$D5/100)*(Assumptions!$C5/100/'Benchmark-equivalent supply'!E$3) -> 49.387863 | F7: ='Seaborne Supply'!F5*(1-Assumptions!$D5/100)*(Assumptions!$C5/100/'Benchmark-equivalent supply'!F$3) -> 69.486576 | G7: ='Seaborne Supply'!G5*(1-Assumptions!$D5/100)*(Assumptions!$C5/100/'Benchmark-equivalent supply'!G$3) -> 106.67778 | H7: ='Seaborne Supply'!H5*(1-Assumptions!$D5/100)*(Assumptions!$C5/100/'Benchmark-equivalent supply'!H$3) -> 142.06526 | I7: ='Seaborne Supply'!I5*(1-Assumptions!$D5/100)*(Assumptions!$C5/100/'Benchmark-equivalent supply'!I$3) -> 145.50094 | J7: ='Seaborne Supply'!J5*(1-Assumptions!$D5/100)*(Assumptions!$C5/100/'Benchmark-equivalent supply'!J$3) -> 146.35986 | ... AB7: ='Seaborne Supply'!AB5*(1-Assumptions!$D5/100)*(Assumptions!$C5/100/'Benchmark-equivalent supply'!AB$3) -> 161.505
A8: Fortescue Iron Bridge Magnetite Project (1 Hub) | C8: ='Seaborne Supply'!C6*(1-Assumptions!$D6/100)*(Assumptions!$C6/100/'Benchmark-equivalent supply'!C$3) -> 0 | D8: ='Seaborne Supply'!D6*(1-Assumptions!$D6/100)*(Assumptions!$C6/100/'Benchmark-equivalent supply'!D$3) -> 0 | E8: ='Seaborne Supply'!E6*(1-Assumptions!$D6/100)*(Assumptions!$C6/100/'Benchmark-equivalent supply'!E$3) -> 0 | F8: ='Seaborne Supply'!F6*(1-Assumptions!$D6/100)*(Assumptions!$C6/100/'Benchmark-equivalent supply'!F$3) -> 0 | G8: ='Seaborne Supply'!G6*(1-Assumptions!$D6/100)*(Assumptions!$C6/100/'Benchmark-equivalent supply'!G$3) -> 0 | H8: ='Seaborne Supply'!H6*(1-Assumptions!$D6/100)*(Assumptions!$C6/100/'Benchmark-equivalent supply'!H$3) -> 0 | I8: ='Seaborne Supply'!I6*(1-Assumptions!$D6/100)*(Assumptions!$C6/100/'Benchmark-equivalent supply'!I$3) -> 0 | J8: ='Seaborne Supply'!J6*(1-Assumptions!$D6/100)*(Assumptions!$C6/100/'Benchmark-equivalent supply'!J$3) -> 0 | ... AB8: ='Seaborne Supply'!AB6*(1-Assumptions!$D6/100)*(Assumptions!$C6/100/'Benchmark-equivalent supply'!AB$3) -> 15.992131
A9: Vale Northern System (3 Hubs) | C9: ='Seaborne Supply'!C7*(1-Assumptions!$D7/100)*(Assumptions!$C7/100/'Benchmark-equivalent supply'!C$3) -> 90.857419 | D9: ='Seaborne Supply'!D7*(1-Assumptions!$D7/100)*(Assumptions!$C7/100/'Benchmark-equivalent supply'!D$3) -> 96.933871 | E9: ='Seaborne Supply'!E7*(1-Assumptions!$D7/100)*(Assumptions!$C7/100/'Benchmark-equivalent supply'!E$3) -> 101.66 | F9: ='Seaborne Supply'!F7*(1-Assumptions!$D7/100)*(Assumptions!$C7/100/'Benchmark-equivalent supply'!F$3) -> 103.20323 | G9: ='Seaborne Supply'!G7*(1-Assumptions!$D7/100)*(Assumptions!$C7/100/'Benchmark-equivalent supply'!G$3) -> 108.31516 | H9: ='Seaborne Supply'!H7*(1-Assumptions!$D7/100)*(Assumptions!$C7/100/'Benchmark-equivalent supply'!H$3) -> 120.27516 | I9: ='Seaborne Supply'!I7*(1-Assumptions!$D7/100)*(Assumptions!$C7/100/'Benchmark-equivalent supply'!I$3) -> 143.7129 | J9: ='Seaborne Supply'!J7*(1-Assumptions!$D7/100)*(Assumptions!$C7/100/'Benchmark-equivalent supply'!J$3) -> 163.48548 | ... AB9: ='Seaborne Supply'!AB7*(1-Assumptions!$D7/100)*(Assumptions!$C7/100/'Benchmark-equivalent supply'!AB$3) -> 186.2623
A10: Vale Southeastern System (3 Hubs) | C10: ='Seaborne Supply'!C8*(1-Assumptions!$D8/100)*(Assumptions!$C8/100/'Benchmark-equivalent supply'!C$3) -> 90.878194 | D10: ='Seaborne Supply'!D8*(1-Assumptions!$D8/100)*(Assumptions!$C8/100/'Benchmark-equivalent supply'!D$3) -> 93.141097 | E10: ='Seaborne Supply'!E8*(1-Assumptions!$D8/100)*(Assumptions!$C8/100/'Benchmark-equivalent supply'!E$3) -> 92.869548 | F10: ='Seaborne Supply'!F8*(1-Assumptions!$D8/100)*(Assumptions!$C8/100/'Benchmark-equivalent supply'!F$3) -> 91.964387 | G10: ='Seaborne Supply'!G8*(1-Assumptions!$D8/100)*(Assumptions!$C8/100/'Benchmark-equivalent supply'!G$3) -> 91.873871 | H10: ='Seaborne Supply'!H8*(1-Assumptions!$D8/100)*(Assumptions!$C8/100/'Benchmark-equivalent supply'!H$3) -> 95.404 | I10: ='Seaborne Supply'!I8*(1-Assumptions!$D8/100)*(Assumptions!$C8/100/'Benchmark-equivalent supply'!I$3) -> 91.149742 | J10: ='Seaborne Supply'!J8*(1-Assumptions!$D8/100)*(Assumptions!$C8/100/'Benchmark-equivalent supply'!J$3) -> 92.507484 | ... AB10: ='Seaborne Supply'!AB8*(1-Assumptions!$D8/100)*(Assumptions!$C8/100/'Benchmark-equivalent supply'!AB$3) -> 80.96
A11: Vale Southern System (2 Hubs) | C11: ='Seaborne Supply'!C9*(1-Assumptions!$D9/100)*(Assumptions!$C9/100/'Benchmark-equivalent supply'!C$3) -> 53.571774 | D11: ='Seaborne Supply'!D9*(1-Assumptions!$D9/100)*(Assumptions!$C9/100/'Benchmark-equivalent supply'!D$3) -> 52.332097 | E11: ='Seaborne Supply'!E9*(1-Assumptions!$D9/100)*(Assumptions!$C9/100/'Benchmark-equivalent supply'!E$3) -> 55.43129 | F11: ='Seaborne Supply'!F9*(1-Assumptions!$D9/100)*(Assumptions!$C9/100/'Benchmark-equivalent supply'!F$3) -> 54.722903 | G11: ='Seaborne Supply'!G9*(1-Assumptions!$D9/100)*(Assumptions!$C9/100/'Benchmark-equivalent supply'!G$3) -> 57.025161 | H11: ='Seaborne Supply'!H9*(1-Assumptions!$D9/100)*(Assumptions!$C9/100/'Benchmark-equivalent supply'!H$3) -> 61.364032 | I11: ='Seaborne Supply'!I9*(1-Assumptions!$D9/100)*(Assumptions!$C9/100/'Benchmark-equivalent supply'!I$3) -> 59.770161 | J11: ='Seaborne Supply'!J9*(1-Assumptions!$D9/100)*(Assumptions!$C9/100/'Benchmark-equivalent supply'!J$3) -> 55.43129 | ... AB11: ='Seaborne Supply'!AB9*(1-Assumptions!$D9/100)*(Assumptions!$C9/100/'Benchmark-equivalent supply'!AB$3) -> 54
A12: Hancock Roy Hill (1 Hub) | C12: ='Seaborne Supply'!C10*(1-Assumptions!$D10/100)*(Assumptions!$C10/100/'Benchmark-equivalent supply'!C$3) -> 0 | D12: ='Seaborne Supply'!D10*(1-Assumptions!$D10/100)*(Assumptions!$C10/100/'Benchmark-equivalent supply'!D$3) -> 0 | E12: ='Seaborne Supply'!E10*(1-Assumptions!$D10/100)*(Assumptions!$C10/100/'Benchmark-equivalent supply'!E$3) -> 0 | F12: ='Seaborne Supply'!F10*(1-Assumptions!$D10/100)*(Assumptions!$C10/100/'Benchmark-equivalent supply'!F$3) -> 0 | G12: ='Seaborne Supply'!G10*(1-Assumptions!$D10/100)*(Assumptions!$C10/100/'Benchmark-equivalent supply'!G$3) -> 0 | H12: ='Seaborne Supply'!H10*(1-Assumptions!$D10/100)*(Assumptions!$C10/100/'Benchmark-equivalent supply'!H$3) -> 0 | I12: ='Seaborne Supply'!I10*(1-Assumptions!$D10/100)*(Assumptions!$C10/100/'Benchmark-equivalent supply'!I$3) -> 12.609935 | J12: ='Seaborne Supply'!J10*(1-Assumptions!$D10/100)*(Assumptions!$C10/100/'Benchmark-equivalent supply'!J$3) -> 27.922 | ... AB12: ='Seaborne Supply'!AB10*(1-Assumptions!$D10/100)*(Assumptions!$C10/100/'Benchmark-equivalent supply'!AB$3) -> 36.069731
A13: MinRes Onslow Iron (1 Hub) | C13: ='Seaborne Supply'!C11*(1-Assumptions!$D11/100)*(Assumptions!$C11/100/'Benchmark-equivalent supply'!C$3) -> 0 | D13: ='Seaborne Supply'!D11*(1-Assumptions!$D11/100)*(Assumptions!$C11/100/'Benchmark-equivalent supply'!D$3) -> 0 | E13: ='Seaborne Supply'!E11*(1-Assumptions!$D11/100)*(Assumptions!$C11/100/'Benchmark-equivalent supply'!E$3) -> 0 | F13: ='Seaborne Supply'!F11*(1-Assumptions!$D11/100)*(Assumptions!$C11/100/'Benchmark-equivalent supply'!F$3) -> 0 | G13: ='Seaborne Supply'!G11*(1-Assumptions!$D11/100)*(Assumptions!$C11/100/'Benchmark-equivalent supply'!G$3) -> 0 | H13: ='Seaborne Supply'!H11*(1-Assumptions!$D11/100)*(Assumptions!$C11/100/'Benchmark-equivalent supply'!H$3) -> 0 | I13: ='Seaborne Supply'!I11*(1-Assumptions!$D11/100)*(Assumptions!$C11/100/'Benchmark-equivalent supply'!I$3) -> 0 | J13: ='Seaborne Supply'!J11*(1-Assumptions!$D11/100)*(Assumptions!$C11/100/'Benchmark-equivalent supply'!J$3) -> 0 | ... AB13: ='Seaborne Supply'!AB11*(1-Assumptions!$D11/100)*(Assumptions!$C11/100/'Benchmark-equivalent supply'!AB$3) -> 30.721967
A14: MinRes Pilbara Hub (1 Hub) | C14: ='Seaborne Supply'!C12*(1-Assumptions!$D12/100)*(Assumptions!$C12/100/'Benchmark-equivalent supply'!C$3) -> 0 | D14: ='Seaborne Supply'!D12*(1-Assumptions!$D12/100)*(Assumptions!$C12/100/'Benchmark-equivalent supply'!D$3) -> 0 | E14: ='Seaborne Supply'!E12*(1-Assumptions!$D12/100)*(Assumptions!$C12/100/'Benchmark-equivalent supply'!E$3) -> 0 | F14: ='Seaborne Supply'!F12*(1-Assumptions!$D12/100)*(Assumptions!$C12/100/'Benchmark-equivalent supply'!F$3) -> 0 | G14: ='Seaborne Supply'!G12*(1-Assumptions!$D12/100)*(Assumptions!$C12/100/'Benchmark-equivalent supply'!G$3) -> 0 | H14: ='Seaborne Supply'!H12*(1-Assumptions!$D12/100)*(Assumptions!$C12/100/'Benchmark-equivalent supply'!H$3) -> 5.0859677 | I14: ='Seaborne Supply'!I12*(1-Assumptions!$D12/100)*(Assumptions!$C12/100/'Benchmark-equivalent supply'!I$3) -> 5.933629 | J14: ='Seaborne Supply'!J12*(1-Assumptions!$D12/100)*(Assumptions!$C12/100/'Benchmark-equivalent supply'!J$3) -> 6.7812903 | ... AB14: ='Seaborne Supply'!AB12*(1-Assumptions!$D12/100)*(Assumptions!$C12/100/'Benchmark-equivalent supply'!AB$3) -> 0
A15: Hancock Atlas Iron (3 Hubs) | C15: ='Seaborne Supply'!C13*(1-Assumptions!$D13/100)*(Assumptions!$C13/100/'Benchmark-equivalent supply'!C$3) -> 5.1077419 | D15: ='Seaborne Supply'!D13*(1-Assumptions!$D13/100)*(Assumptions!$C13/100/'Benchmark-equivalent supply'!D$3) -> 5.5333871 | E15: ='Seaborne Supply'!E13*(1-Assumptions!$D13/100)*(Assumptions!$C13/100/'Benchmark-equivalent supply'!E$3) -> 6.3846774 | F15: ='Seaborne Supply'!F13*(1-Assumptions!$D13/100)*(Assumptions!$C13/100/'Benchmark-equivalent supply'!F$3) -> 8.0872581 | G15: ='Seaborne Supply'!G13*(1-Assumptions!$D13/100)*(Assumptions!$C13/100/'Benchmark-equivalent supply'!G$3) -> 10.385742 | H15: ='Seaborne Supply'!H13*(1-Assumptions!$D13/100)*(Assumptions!$C13/100/'Benchmark-equivalent supply'!H$3) -> 11.918065 | I15: ='Seaborne Supply'!I13*(1-Assumptions!$D13/100)*(Assumptions!$C13/100/'Benchmark-equivalent supply'!I$3) -> 12.34371 | J15: ='Seaborne Supply'!J13*(1-Assumptions!$D13/100)*(Assumptions!$C13/100/'Benchmark-equivalent supply'!J$3) -> 7.6616129 | ... AB15: ='Seaborne Supply'!AB13*(1-Assumptions!$D13/100)*(Assumptions!$C13/100/'Benchmark-equivalent supply'!AB$3) -> 4.845377
A16: CITIC Sino Iron (1 Hub) | C16: ='Seaborne Supply'!C14*(1-Assumptions!$D14/100)*(Assumptions!$C14/100/'Benchmark-equivalent supply'!C$3) -> 0 | D16: ='Seaborne Supply'!D14*(1-Assumptions!$D14/100)*(Assumptions!$C14/100/'Benchmark-equivalent supply'!D$3) -> 0 | E16: ='Seaborne Supply'!E14*(1-Assumptions!$D14/100)*(Assumptions!$C14/100/'Benchmark-equivalent supply'!E$3) -> 0 | F16: ='Seaborne Supply'!F14*(1-Assumptions!$D14/100)*(Assumptions!$C14/100/'Benchmark-equivalent supply'!F$3) -> 0 | G16: ='Seaborne Supply'!G14*(1-Assumptions!$D14/100)*(Assumptions!$C14/100/'Benchmark-equivalent supply'!G$3) -> 0 | H16: ='Seaborne Supply'!H14*(1-Assumptions!$D14/100)*(Assumptions!$C14/100/'Benchmark-equivalent supply'!H$3) -> 10.609677 | I16: ='Seaborne Supply'!I14*(1-Assumptions!$D14/100)*(Assumptions!$C14/100/'Benchmark-equivalent supply'!I$3) -> 15.432258 | J16: ='Seaborne Supply'!J14*(1-Assumptions!$D14/100)*(Assumptions!$C14/100/'Benchmark-equivalent supply'!J$3) -> 16.396774 | ... AB16: ='Seaborne Supply'!AB14*(1-Assumptions!$D14/100)*(Assumptions!$C14/100/'Benchmark-equivalent supply'!AB$3) -> 22.547541
... A75: Opaque Producer Supply | C75: ='Seaborne Supply'!C73*(1-Assumptions!$D73/100)*(Assumptions!$C73/100/'Benchmark-equivalent supply'!C$3) -> 183.94732 | D75: ='Seaborne Supply'!D73*(1-Assumptions!$D73/100)*(Assumptions!$C73/100/'Benchmark-equivalent supply'!D$3) -> 193.55316 | E75: ='Seaborne Supply'!E73*(1-Assumptions!$D73/100)*(Assumptions!$C73/100/'Benchmark-equivalent supply'!E$3) -> 182.51094 | F75: ='Seaborne Supply'!F73*(1-Assumptions!$D73/100)*(Assumptions!$C73/100/'Benchmark-equivalent supply'!F$3) -> 214.56032 | G75: ='Seaborne Supply'!G73*(1-Assumptions!$D73/100)*(Assumptions!$C73/100/'Benchmark-equivalent supply'!G$3) -> 211.05913 | H75: ='Seaborne Supply'!H73*(1-Assumptions!$D73/100)*(Assumptions!$C73/100/'Benchmark-equivalent supply'!H$3) -> 132.14761 | I75: ='Seaborne Supply'!I73*(1-Assumptions!$D73/100)*(Assumptions!$C73/100/'Benchmark-equivalent supply'!I$3) -> 155.4889 | J75: ='Seaborne Supply'!J73*(1-Assumptions!$D73/100)*(Assumptions!$C73/100/'Benchmark-equivalent supply'!J$3) -> 158.72077 | ... AB75: ='Seaborne Supply'!AB73*(1-Assumptions!$D73/100)*(Assumptions!$C73/100/'Benchmark-equivalent supply'!AB$3) -> 74.36541
A76: Total seaborne Supply | C76: 1123.6 | D76: 1148.3 | E76: 1214 | F76: 1344 | G76: 1488.5 | H76: 1512 | I76: 1591.6 | J76: 1646.3 | K76: 1667.3 | L76: 1603.9 | M76: 1656.2 | N76: 1659.4 | O76: 1586.8 | P76: 1712 | Q76: 1740.5 | R76: 1761 | S76: 1789 | T76: 1844 | U76: 1891 | V76: 1931 | W76: 1950 | X76: 1965 | Y76: 1975 | Z76: 1985 | AA76: 1985 | AB76: 1980

Sheet FOB Cost
A1: FOB by Asset – Excl. Royalties & Freight, USD wmt | 2% Inflation
A2: Asset | C2: 2010 | D2: 2011 | E2: 2012 | F2: 2013 | G2: 2014 | H2: 2015 | I2: 2016 | J2: 2017 | K2: 2018 | L2: 2019 | M2: 2020 | N2: 2021 | O2: 2022 | P2: 2023 | Q2: 2024 | R2: 2025 | S2: 2026 | T2: 2027 | U2: 2028 | V2: 2029 | W2: 2030 | X2: 2031 | Y2: 2032 | Z2: 2033 | AA2: 2034 | AB2: 2035
A3: BHP WAIO (5 Hubs) | C3: 22 | D3: 28.5 | E3: 29.9 | F3: 29.4 | G3: 27 | H3: 18.7 | I3: 15.1 | J3: 14.6 | K3: 14.3 | L3: 14.2 | M3: 12.6 | N3: 14.8 | O3: 16.8 | P3: 17.8 | Q3: 18.2 | R3: 18.6 | S3: 19.7 | T3: 21 | U3: 20 | V3: 19 | W3: 18 | X3: 17.8 | Y3: 18.2 | Z3: 18.5 | AA3: 18.9 | AB3: 19.3
A4: Rio Tinto Pilbara (8 Hubs) | C4: 20.5 | D4: 23.9 | E4: 21.8 | F4: 20.2 | G4: 19.5 | H4: 14.9 | I4: 13.7 | J4: 13.4 | K4: 13.3 | L4: 14.4 | M4: 15.4 | N4: 18.6 | O4: 21.7 | P4: 21.5 | Q4: 23 | R4: 23.5 | S4: 24.25 | T4: 23.6 | U4: 22.9 | V4: 22.2 | W4: 21.6 | X4: 22 | Y4: 22.5 | Z4: 22.9 | AA4: 23.4 | AB4: 23.8
A5: Fortescue Hematite (3 Hubs) | C5: 31 | D5: 44 | E5: 48 | F5: 44 | G5: 34 | H5: 27 | I5: 15.43 | J5: 12.82 | K5: 12.36 | L5: 13.11 | M5: 12.94 | N5: 13.93 | O5: 15.91 | P5: 17.54 | Q5: 18.24 | R5: 17.99 | S5: 18.74 | T5: 21.13 | U5: 20.5 | V5: 19.8 | W5: 19 | X5: 18.8 | Y5: 19.2 | Z5: 19.6 | AA5: 20 | AB5: 20.3
A6: Fortescue Iron Bridge Magnetite Project (1 Hub) | C6: 0 | D6: 0 | E6: 0 | F6: 0 | G6: 0 | H6: 0 | I6: 0 | J6: 0 | K6: 0 | L6: 0 | M6: 0 | N6: 0 | O6: 0 | P6: 50 | Q6: 48 | R6: 46 | S6: 45 | T6: 45.9 | U6: 46.8 | V6: 47.8 | W6: 48.7 | X6: 49.7 | Y6: 50.7 | Z6: 51.7 | AA6: 52.7 | AB6: 53.8
A7: Vale Northern System (3 Hubs) | C7: 19 | D7: 21.5 | E7: 19.5 | F7: 17.5 | G7: 18 | H7: 12.7 | I7: 10.5 | J7: 11.5 | K7: 11.5 | L7: 11.8 | M7: 11.4 | N7: 13.7 | O7: 16 | P7: 18.5 | Q7: 18 | R7: 17.5 | S7: 19.2 | T7: 17.8 | U7: 16.8 | V7: 16 | W7: 15 | X7: 15.3 | Y7: 15.6 | Z7: 15.9 | AA7: 16.2 | AB7: 16.6
A8: Vale Southeastern System (3 Hubs) | C8: 25 | D8: 28 | E8: 25.5 | F8: 23.5 | G8: 24 | H8: 17.5 | I8: 16 | J8: 17 | K8: 15.8 | L8: 18.5 | M8: 18 | N8: 22 | O8: 25.5 | P8: 27.5 | Q8: 27 | R8: 26.5 | S8: 28.5 | T8: 27 | U8: 26 | V8: 25.5 | W8: 24.5 | X8: 25 | Y8: 25.5 | Z8: 26 | AA8: 26.5 | AB8: 27.1
A9: Vale Southern System (2 Hubs) | C9: 21.5 | D9: 24 | E9: 22 | F9: 20 | G9: 20.5 | H9: 12.5 | I9: 13 | J9: 14.5 | K9: 13.6 | L9: 16 | M9: 16.5 | N9: 20 | O9: 23.5 | P9: 25.5 | Q9: 25 | R9: 24.5 | S9: 26.5 | T9: 25 | U9: 24 | V9: 23.5 | W9: 22.5 | X9: 23 | Y9: 23.4 | Z9: 23.9 | AA9: 24.4 | AB9: 24.8
A10: Hancock Roy Hill (1 Hub) | C10: 0 | D10: 0 | E10: 0 | F10: 0 | G10: 0 | H10: 0 | I10: 27 | J10: 25 | K10: 24 | L10: 23 | M10: 22 | N10: 23 | O10: 24 | P10: 25 | Q10: 25 | R10: 26 | S10: 26 | T10: 25.5 | U10: 25 | V10: 24.5 | W10: 24 | X10: 24.5 | Y10: 25 | Z10: 25.5 | AA10: 26 | AB10: 26.5
A11: MinRes Onslow Iron (1 Hub) | C11: 0 | D11: 0 | E11: 0 | F11: 0 | G11: 0 | H11: 0 | I11: 0 | J11: 0 | K11: 0 | L11: 0 | M11: 0 | N11: 0 | O11: 0 | P11: 0 | Q11: 55 | R11: 40.8 | S11: 35.3 | T11: 39.2 | U11: 38.5 | V11: 38 | W11: 38 | X11: 38.8 | Y11: 39.5 | Z11: 40.3 | AA11: 41.1 | AB11: 42
A12: MinRes Pilbara Hub (1 Hub) | C12: 0 | D12: 0 | E12: 0 | F12: 0 | G12: 0 | H12: 31 | I12: 30 | J12: 30.5 | K12: 34 | L12: 34 | M12: 37.5 | N12: 53.5 | O12: 44.2 | P12: 47.9 | Q12: 48.6 | R12: 49.2 | S12: 53.6 | T12: 53.6 | U12: 54.7 | V12: 55.8 | W12: 56.9 | X12: 0 | Y12: 0 | Z12: 0 | AA12: 0 | AB12: 0
A13: Hancock Atlas Iron (3 Hubs) | C13: 45 | D13: 43 | E13: 45 | F13: 48 | G13: 46 | H13: 35 | I13: 25.5 | J13: 26.5 | K13: 29 | L13: 28.5 | M13: 27.5 | N13: 29.5 | O13: 31.5 | P13: 31 | Q13: 29.5 | R13: 29 | S13: 29.6 | T13: 30.2 | U13: 30.8 | V13: 31.4 | W13: 32 | X13: 32.7 | Y13: 33.3 | Z13: 34 | AA13: 34.7 | AB13: 35.4
A14: CITIC Sino Iron (1 Hub) | C14: - | D14: - | E14: - | F14: 0 | G14: 0 | H14: 105 | I14: 93 | J14: 83 | K14: 75 | L14: 69 | M14: 65 | N14: 66 | O14: 67 | P14: 69 | Q14: 74 | R14: 77 | S14: 79 | T14: 78 | U14: 76 | V14: 75 | W14: 76.5 | X14: 78 | Y14: 79.6 | Z14: 81.2 | AA14: 82.8 | AB14: 84.5
A15: Kumba (2 Hubs) | C15: 24.5 | D15: 29 | E15: 32.5 | F15: 35.5 | G15: 33.5 | H15: 30.5 | I15: 26.7 | J15: 31.8 | K15: 31.8 | L15: 32.9 | M15: 31.2 | N15: 39 | O15: 40 | P15: 41 | Q15: 39 | R15: 40 | S15: 45 | T15: 42 | U15: 41 | V15: 40.5 | W15: 40.5 | X15: 41.3 | Y15: 42.1 | Z15: 43 | AA15: 43.8 | AB15: 44.7
A16: Champion Iron Bloom Lake (1 Hub) | C16: 60 | D16: 74 | E16: 85 | F16: 92.5 | G16: 82.5 | H16: - | I16: - | J16: - | K16: 37.5 | L16: 37.7 | M16: 39.6 | N16: 41 | O16: 47 | P16: 55.9 | Q16: 56.2 | R16: 55.5 | S16: 56.6 | T16: 59 | U16: 58 | V16: 57 | W16: 58.1 | X16: 59.3 | Y16: 60.5 | Z16: 61.7 | AA16: 62.9 | AB16: 64.2
A17: Rio Tinto IOC (1 Hub) | C17: 54 | D17: 58 | E17: 62 | F17: 64 | G17: 62 | H17: 47.1 | I17: 43.6 | J17: 44.1 | K17: 52.7 | L17: 52.3 | M17: 52 | N17: 65.3 | O17: 69.3 | P17: 73.8 | Q17: 80 | R17: 84.3 | S17: 88 | T17: 86 | U17: 83 | V17: 80 | W17: 78 | X17: 79.6 | Y17: 81.2 | Z17: 82.8 | AA17: 84.4 | AB17: 86.1
A18: CSN (1 Hub) | C18: 27 | D18: 30 | E18: 31 | F18: 30 | G18: 30 | H18: 22 | I18: 20 | J18: 21.5 | K18: 20 | L18: 19.5 | M18: 17 | N18: 19.7 | O18: 22.1 | P18: 21.8 | Q18: 20.4 | R18: 21.5 | S18: 22.8 | T18: 22 | U18: 21 | V18: 21.4 | W18: 21.8 | X18: 22.3 | Y18: 22.7 | Z18: 23.2 | AA18: 23.7 | AB18: 24.1
A19: Anglo Minas-Rio (1 Hub) | C19: - | D19: - | E19: - | F19: - | G19: 65 | H19: 60 | I19: 28 | J19: 30 | K19: 30 | L19: 21 | M19: 21 | N19: 24 | O19: 35 | P19: 33 | Q19: 30 | R19: 32 | S19: 36 | T19: 36 | U19: 36 | V19: 36 | W19: 36.7 | X19: 37.5 | Y19: 38.2 | Z19: 39 | AA19: 39.7 | AB19: 40.5
A20: Vale & BHP Germano (1 Hub) | C20: 50 | D20: 55 | E20: 58 | F20: 57.1 | G20: 53.4 | H20: 46 | I20: 46 | J20: - | K20: - | L20: - | M20: - | N20: 50 | O20: 55 | P20: 53.9 | Q20: 51.2 | R20: 42.8 | S20: 48 | T20: 47 | U20: 44 | V20: 42 | W20: 42.8 | X20: 43.7 | Y20: 44.5 | Z20: 45.4 | AA20: 46.3 | AB20: 47.2
A21: LKAB (3 Hubs) | C21: 45 | D21: 51 | E21: 54 | F21: 56 | G21: 53 | H21: 50 | I21: 47 | J21: 46 | K21: 45 | L21: 47 | M21: 46 | N21: 49 | O21: 54 | P21: 56 | Q21: 50 | R21: 48 | S21: 48 | T21: 47 | U21: 46 | V21: 46 | W21: 46.9 | X21: 47.8 | Y21: 48.8 | Z21: 49.8 | AA21: 50.8 | AB21: 51.8
A22: SNIM (3 Hubs) | C22: 40 | D22: 45 | E22: 46 | F22: 44 | G22: 43 | H22: 34 | I22: 25 | J22: 30 | K22: 32 | L22: 33 | M22: 31.5 | N22: 39 | O22: 46.5 | P22: 51 | Q22: 52 | R22: 50.5 | S22: 49 | T22: 47 | U22: 45 | V22: 43.5 | W22: 43 | X22: 43.9 | Y22: 44.7 | Z22: 45.6 | AA22: 46.5 | AB22: 47.5
A23: Shougang Hierro Perú (1 Hub) | C23: 24 | D23: 37.5 | E23: 35.5 | F23: 35.3 | G23: 30 | H23: 20.8 | I23: 20.3 | J23: 22 | K23: 25 | L23: 25.7 | M23: 37.5 | N23: 38.3 | O23: 42.3 | P23: 42.6 | Q23: 41 | R23: 45.1 | S23: 49 | T23: 46 | U23: 44 | V23: 43 | W23: 43.9 | X23: 44.8 | Y23: 45.7 | Z23: 46.6 | AA23: 47.5 | AB23: 48.5
A24: Ferrexpo (2 Hubs) | C24: 49 | D24: 61 | E24: 70.5 | F24: 71 | G24: 59 | H24: 42 | I24: 37 | J24: 42 | K24: 53 | L24: 58 | M24: 52 | N24: 67 | O24: 100 | P24: 96 | Q24: 85 | R24: 74 | S24: 82 | T24: 72 | U24: 65 | V24: 61 | W24: 59 | X24: 60.2 | Y24: 61.4 | Z24: 62.6 | AA24: 63.9 | AB24: 65.1
A25: Metinvest Iron Ore (3 Hubs) | C25: 53 | D25: 64 | E25: 72 | F25: 73 | G25: 62 | H25: 47 | I25: 42 | J25: 46 | K25: 52 | L25: 57 | M25: 54 | N25: 69 | O25: 95 | P25: 87 | Q25: 73 | R25: 70 | S25: 73 | T25: 66 | U25: 60 | V25: 57 | W25: 55 | X25: 56.1 | Y25: 57.2 | Z25: 58.4 | AA25: 59.5 | AB25: 60.7
A26: Vedanta (2 Hubs) | C26: 17 | D26: 18 | E26: 18 | F26: 19 | G26: 0 | H26: 0 | I26: 14.3 | J26: 14 | K26: 15.5 | L26: 18 | M26: 18.5 | N26: 19.5 | O26: 21 | P26: 21.5 | Q26: 22 | R26: 22 | S26: 22.4 | T26: 22.9 | U26: 23.3 | V26: 23.8 | W26: 24.3 | X26: 24.8 | Y26: 25.2 | Z26: 25.8 | AA26: 26.3 | AB26: 26.8
A27: NMDC (2 Hubs) | C27: 50 | D27: 54 | E27: 58 | F27: 58 | G27: 56 | H27: 55 | I27: 54 | J27: 53 | K27: 52 | L27: 50 | M27: 48 | N27: 52 | O27: 0 | P27: 0 | Q27: 0 | R27: 50 | S27: 51 | T27: 52 | U27: 53.1 | V27: 54.1 | W27: 55.2 | X27: 56.3 | Y27: 57.4 | Z27: 58.6 | AA27: 59.8 | AB27: 61
A28: Rungta Mines (1 Hub) | C28: 29 | D28: 31 | E28: 32 | F28: 31 | G28: 29 | H28: 26 | I28: 0 | J28: 24 | K28: 25 | L28: 26 | M28: 25 | N28: 28 | O28: 31 | P28: 30 | Q28: 29 | R28: 29.5 | S28: 30.1 | T28: 30.7 | U28: 31.3 | V28: 31.9 | W28: 32.5 | X28: 33.2 | Y28: 33.8 | Z28: 34.5 | AA28: 35.2 | AB28: 35.9
A29: Gol-e-Gohar (1 Hub) | C29: 44 | D29: 45 | E29: 43 | F29: 44 | G29: 45 | H29: 46 | I29: 47 | J29: 46 | K29: 44 | L29: 43 | M29: 0 | N29: 45 | O29: 48 | P29: 51 | Q29: 49 | R29: 50 | S29: 50 | T29: 49 | U29: 48 | V29: 48 | W29: 49 | X29: 50 | Y29: 51 | Z29: 52 | AA29: 53 | AB29: 54.1
A30: Goharzamin (1 Hub) | C30: 0 | D30: 0 | E30: 0 | F30: 0 | G30: 0 | H30: =-O270 -> 0 | I30: 54 | J30: 51 | K30: 49 | L30: 48 | M30: 48 | N30: 50 | O30: 53 | P30: 56 | Q30: 53 | R30: 54 | S30: 54 | T30: 53 | U30: 52 | V30: 52 | W30: 53 | X30: 54.1 | Y30: 55.2 | Z30: 56.3 | AA30: 57.4 | AB30: 58.6
A31: Chadormalu (1 Hub) | C31: 46 | D31: 47 | E31: 45 | F31: 46 | G31: 47 | H31: 48 | I31: 49 | J31: 48 | K31: 46 | L31: 45 | M31: 0 | N31: 0 | O31: 0 | P31: 0 | Q31: 0 | R31: 0 | S31: 0 | T31: 51 | U31: 50 | V31: 50 | W31: 51 | X31: 52 | Y31: 53.1 | Z31: 54.1 | AA31: 55.2 | AB31: 56.3
A32: Sangan Iron Ore (1 Hub) | C32: 34 | D32: 35 | E32: 36 | F32: 36 | G32: 35 | H32: 35 | I32: 36 | J32: 36 | K32: 35 | L32: 34 | M32: 0 | N32: 0 | O32: 0 | P32: 0 | Q32: 0 | R32: 0 | S32: 0 | T32: 0 | U32: 0 | V32: 0 | W32: 0 | X32: 0 | Y32: 0 | Z32: 0 | AA32: 0 | AB32: 0
A33: Iran Central Iron Ore (1 Hub) | C33: 47 | D33: 48 | E33: 46 | F33: 47 | G33: 48 | H33: 49 | I33: 50 | J33: 49 | K33: 47 | L33: 46 | M33: 46 | N33: 48 | O33: 51 | P33: 54 | Q33: 52 | R33: 53 | S33: 0 | T33: 52 | U33: 51 | V33: 51 | W33: 52 | X33: 53.1 | Y33: 54.1 | Z33: 55.2 | AA33: 56.3 | AB33: 57.4
A34: Sirjan Iranian Steel (1 Hub) | C34: 0 | D34: 0 | E34: 0 | F34: 0 | G34: 0 | H34: 0 | I34: 0 | J34: 0 | K34: 50 | L34: 49 | M34: 0 | N34: 51 | O34: 54 | P34: 57 | Q34: 55 | R34: 56 | S34: 56 | T34: 55 | U34: 54 | V34: 54 | W34: 55.1 | X34: 56.2 | Y34: 57.3 | Z34: 58.5 | AA34: 59.6 | AB34: 60.8
A35: Opal Parsian Sangan (1 Hub) | C35: 0 | D35: 0 | E35: 0 | F35: 0 | G35: 0 | H35: 0 | I35: 0 | J35: 0 | K35: 0 | L35: 0 | M35: 0 | N35: 0 | O35: 0 | P35: 65 | Q35: 63 | R35: 64 | S35: 65 | T35: 64 | U35: 62 | V35: 62 | W35: 63.2 | X35: 64.5 | Y35: 65.8 | Z35: 67.1 | AA35: 68.4 | AB35: 69.8
A36: Marampa (1 Hub) | C36: 0 | D36: 0 | E36: 72 | F36: 57 | G36: 50 | H36: 0 | I36: 0 | J36: 0 | K36: 0 | L36: 43 | M36: 0 | N36: 49 | O36: 47 | P36: 44 | Q36: 44.5 | R36: 42 | S36: 40 | T36: 40.8 | U36: 41.6 | V36: 42.4 | W36: 43.3 | X36: 44.2 | Y36: 45 | Z36: 45.9 | AA36: 46.9 | AB36: 47.8
A37: Tonkolili (1 Hub) | C37: 0 | D37: 55 | E37: 49 | F37: 43 | G37: 38 | H37: 38 | I37: 40 | J37: 42 | K37: 0 | L37: 0 | M37: 0 | N37: 34 | O37: 35 | P37: 36 | Q37: 37 | R37: 40 | S37: 43 | T37: 43.9 | U37: 44.7 | V37: 45.6 | W37: 46.5 | X37: 47.5 | Y37: 48.4 | Z37: 49.4 | AA37: 50.4 | AB37: 51.4
A38: Simandou WCS Blocks 1&2 (1 Hub) | C38: 0 | D38: 0 | E38: 0 | F38: 0 | G38: 0 | H38: 0 | I38: 0 | J38: 0 | K38: 0 | L38: 0 | M38: 0 | N38: 0 | O38: 0 | P38: 0 | Q38: 0 | R38: 23.4 | S38: 23.9 | T38: 24.4 | U38: 24.8 | V38: 25.3 | W38: 25.8 | X38: 26.4 | Y38: 26.9 | Z38: 27.4 | AA38: 28 | AB38: 28.5
A39: Simandou SimFer Blocks 3&4 (1 Hub) | C39: 0 | D39: 0 | E39: 0 | F39: 0 | G39: 0 | H39: 0 | I39: 0 | J39: 0 | K39: 0 | L39: 0 | M39: 0 | N39: 0 | O39: 0 | P39: 0 | Q39: 0 | R39: 25.5 | S39: 26 | T39: 26.5 | U39: 27 | V39: 27.6 | W39: 28.1 | X39: 28.7 | Y39: 29.3 | Z39: 29.9 | AA39: 30.5 | AB39: 31.1
A40: Los Colorados (1 Hub) | C40: 43.5 | D40: 50.5 | E40: 53.5 | F40: 55.9 | G40: 47.7 | H40: 34.4 | I40: 31.5 | J40: 32.5 | K40: 60.5 | L40: 47.8 | M40: 59.7 | N40: 45 | O40: 50 | P40: 52 | Q40: 57.2 | R40: 50.2 | S40: 47.5 | T40: 45.5 | U40: 44.5 | V40: 43.5 | W40: 44.4 | X40: 45.3 | Y40: 46.3 | Z40: 47.2 | AA40: 48.2 | AB40: 49.2
...

Sheet Freight to Qingdao
A1: Freight Cost to Qingdao by Asset, USD wmt
A2: Baltic C5 (Western Australia–Qingdao) and C3 (Brazil–Qingdao) freight benchmarks; Historical values are rounded annual averages from shipping market reports; other assets use the nearest Baltic route scaled by a fixed asset-specific multiplier
A3: Route / asset | B3: Method | C3: 2010 | D3: 2011 | E3: 2012 | F3: 2013 | G3: 2014 | H3: 2015 | I3: 2016 | J3: 2017 | K3: 2018 | L3: 2019 | M3: 2020 | N3: 2021 | O3: 2022 | P3: 2023 | Q3: 2024 | R3: 2025 | S3: 2026 | T3: 2027 | U3: 2028 | V3: 2029 | W3: 2030 | X3: 2031 | Y3: 2032 | Z3: 2033 | AA3: 2034 | AB3: 2035
A4: Baltic C5: Western Australia to Qingdao | C4: 10.4 | D4: 9.1 | E4: 7.8 | F4: 8.8 | G4: 8.1 | H4: 4.9 | I4: 4.5 | J4: 6.8 | K4: 7.6 | L4: 7.7 | M4: 6.7 | N4: 12.1 | O4: 9.9 | P4: 8.7 | Q4: 10.1 | R4: 9.1 | S4: 12.5 | T4: 10.8 | U4: 10.2 | V4: 9.8 | W4: 10 | X4: 10.2 | Y4: 10.4 | Z4: 10.6 | AA4: 10.8 | AB4: 11
A5: Baltic C3: Brazil (Tubarao) to Qingdao | C5: 26.2 | D5: 22.5 | E5: 19.7 | F5: 21.1 | G5: 20.6 | H5: 11.2 | I5: 9.1 | J5: 15.2 | K5: 18.4 | L5: 18.6 | M5: 14.8 | N5: 26.7 | O5: 24 | P5: 21 | Q5: 25 | R5: 21.9 | S5: 31 | T5: 25.5 | U5: 23.2 | V5: 21.8 | W5: 22.2 | X5: 22.7 | Y5: 23.1 | Z5: 23.6 | AA5: 24.1 | AB5: 24.6
A7: BHP WAIO (5 Hubs) | B7: Baltic C5 x 1.00 | C7: =Assumptions!$H3*IF(LEFT($B7,9)="Baltic C5",C$4,C$5) -> 10.4 | D7: =Assumptions!$H3*IF(LEFT($B7,9)="Baltic C5",D$4,D$5) -> 9.1 | E7: =Assumptions!$H3*IF(LEFT($B7,9)="Baltic C5",E$4,E$5) -> 7.8 | F7: =Assumptions!$H3*IF(LEFT($B7,9)="Baltic C5",F$4,F$5) -> 8.8 | G7: =Assumptions!$H3*IF(LEFT($B7,9)="Baltic C5",G$4,G$5) -> 8.1 | H7: =Assumptions!$H3*IF(LEFT($B7,9)="Baltic C5",H$4,H$5) -> 4.9 | I7: =Assumptions!$H3*IF(LEFT($B7,9)="Baltic C5",I$4,I$5) -> 4.5 | J7: =Assumptions!$H3*IF(LEFT($B7,9)="Baltic C5",J$4,J$5) -> 6.8 | ... AB7: =Assumptions!$H3*IF(LEFT($B7,9)="Baltic C5",AB$4,AB$5) -> 11
A8: Rio Tinto Pilbara (8 Hubs) | B8: Baltic C5 x 1.00 | C8: =Assumptions!$H4*IF(LEFT($B8,9)="Baltic C5",C$4,C$5) -> 10.4 | D8: =Assumptions!$H4*IF(LEFT($B8,9)="Baltic C5",D$4,D$5) -> 9.1 | E8: =Assumptions!$H4*IF(LEFT($B8,9)="Baltic C5",E$4,E$5) -> 7.8 | F8: =Assumptions!$H4*IF(LEFT($B8,9)="Baltic C5",F$4,F$5) -> 8.8 | G8: =Assumptions!$H4*IF(LEFT($B8,9)="Baltic C5",G$4,G$5) -> 8.1 | H8: =Assumptions!$H4*IF(LEFT($B8,9)="Baltic C5",H$4,H$5) -> 4.9 | I8: =Assumptions!$H4*IF(LEFT($B8,9)="Baltic C5",I$4,I$5) -> 4.5 | J8: =Assumptions!$H4*IF(LEFT($B8,9)="Baltic C5",J$4,J$5) -> 6.8 | ... AB8: =Assumptions!$H4*IF(LEFT($B8,9)="Baltic C5",AB$4,AB$5) -> 11
A9: Fortescue Hematite (3 Hubs) | B9: Baltic C5 x 1.00 | C9: =Assumptions!$H5*IF(LEFT($B9,9)="Baltic C5",C$4,C$5) -> 10.4 | D9: =Assumptions!$H5*IF(LEFT($B9,9)="Baltic C5",D$4,D$5) -> 9.1 | E9: =Assumptions!$H5*IF(LEFT($B9,9)="Baltic C5",E$4,E$5) -> 7.8 | F9: =Assumptions!$H5*IF(LEFT($B9,9)="Baltic C5",F$4,F$5) -> 8.8 | G9: =Assumptions!$H5*IF(LEFT($B9,9)="Baltic C5",G$4,G$5) -> 8.1 | H9: =Assumptions!$H5*IF(LEFT($B9,9)="Baltic C5",H$4,H$5) -> 4.9 | I9: =Assumptions!$H5*IF(LEFT($B9,9)="Baltic C5",I$4,I$5) -> 4.5 | J9: =Assumptions!$H5*IF(LEFT($B9,9)="Baltic C5",J$4,J$5) -> 6.8 | ... AB9: =Assumptions!$H5*IF(LEFT($B9,9)="Baltic C5",AB$4,AB$5) -> 11
A10: Fortescue Iron Bridge Magnetite Project (1 Hub) | B10: Baltic C5 x 1.00 | C10: =Assumptions!$H6*IF(LEFT($B10,9)="Baltic C5",C$4,C$5) -> 10.4 | D10: =Assumptions!$H6*IF(LEFT($B10,9)="Baltic C5",D$4,D$5) -> 9.1 | E10: =Assumptions!$H6*IF(LEFT($B10,9)="Baltic C5",E$4,E$5) -> 7.8 | F10: =Assumptions!$H6*IF(LEFT($B10,9)="Baltic C5",F$4,F$5) -> 8.8 | G10: =Assumptions!$H6*IF(LEFT($B10,9)="Baltic C5",G$4,G$5) -> 8.1 | H10: =Assumptions!$H6*IF(LEFT($B10,9)="Baltic C5",H$4,H$5) -> 4.9 | I10: =Assumptions!$H6*IF(LEFT($B10,9)="Baltic C5",I$4,I$5) -> 4.5 | J10: =Assumptions!$H6*IF(LEFT($B10,9)="Baltic C5",J$4,J$5) -> 6.8 | ... AB10: =Assumptions!$H6*IF(LEFT($B10,9)="Baltic C5",AB$4,AB$5) -> 11
A11: Vale Northern System (3 Hubs) | B11: Baltic C3 x 1.06 | C11: =Assumptions!$H7*IF(LEFT($B11,9)="Baltic C5",C$4,C$5) -> 27.772 | D11: =Assumptions!$H7*IF(LEFT($B11,9)="Baltic C5",D$4,D$5) -> 23.85 | E11: =Assumptions!$H7*IF(LEFT($B11,9)="Baltic C5",E$4,E$5) -> 20.882 | F11: =Assumptions!$H7*IF(LEFT($B11,9)="Baltic C5",F$4,F$5) -> 22.366 | G11: =Assumptions!$H7*IF(LEFT($B11,9)="Baltic C5",G$4,G$5) -> 21.836 | H11: =Assumptions!$H7*IF(LEFT($B11,9)="Baltic C5",H$4,H$5) -> 11.872 | I11: =Assumptions!$H7*IF(LEFT($B11,9)="Baltic C5",I$4,I$5) -> 9.646 | J11: =Assumptions!$H7*IF(LEFT($B11,9)="Baltic C5",J$4,J$5) -> 16.112 | ... AB11: =Assumptions!$H7*IF(LEFT($B11,9)="Baltic C5",AB$4,AB$5) -> 26.076
A12: Vale Southeastern System (3 Hubs) | B12: Baltic C3 x 1.00 | C12: =Assumptions!$H8*IF(LEFT($B12,9)="Baltic C5",C$4,C$5) -> 26.2 | D12: =Assumptions!$H8*IF(LEFT($B12,9)="Baltic C5",D$4,D$5) -> 22.5 | E12: =Assumptions!$H8*IF(LEFT($B12,9)="Baltic C5",E$4,E$5) -> 19.7 | F12: =Assumptions!$H8*IF(LEFT($B12,9)="Baltic C5",F$4,F$5) -> 21.1 | G12: =Assumptions!$H8*IF(LEFT($B12,9)="Baltic C5",G$4,G$5) -> 20.6 | H12: =Assumptions!$H8*IF(LEFT($B12,9)="Baltic C5",H$4,H$5) -> 11.2 | I12: =Assumptions!$H8*IF(LEFT($B12,9)="Baltic C5",I$4,I$5) -> 9.1 | J12: =Assumptions!$H8*IF(LEFT($B12,9)="Baltic C5",J$4,J$5) -> 15.2 | ... AB12: =Assumptions!$H8*IF(LEFT($B12,9)="Baltic C5",AB$4,AB$5) -> 24.6
A13: Vale Southern System (2 Hubs) | B13: Baltic C3 x 1.01 | C13: =Assumptions!$H9*IF(LEFT($B13,9)="Baltic C5",C$4,C$5) -> 26.462 | D13: =Assumptions!$H9*IF(LEFT($B13,9)="Baltic C5",D$4,D$5) -> 22.725 | E13: =Assumptions!$H9*IF(LEFT($B13,9)="Baltic C5",E$4,E$5) -> 19.897 | F13: =Assumptions!$H9*IF(LEFT($B13,9)="Baltic C5",F$4,F$5) -> 21.311 | G13: =Assumptions!$H9*IF(LEFT($B13,9)="Baltic C5",G$4,G$5) -> 20.806 | H13: =Assumptions!$H9*IF(LEFT($B13,9)="Baltic C5",H$4,H$5) -> 11.312 | I13: =Assumptions!$H9*IF(LEFT($B13,9)="Baltic C5",I$4,I$5) -> 9.191 | J13: =Assumptions!$H9*IF(LEFT($B13,9)="Baltic C5",J$4,J$5) -> 15.352 | ... AB13: =Assumptions!$H9*IF(LEFT($B13,9)="Baltic C5",AB$4,AB$5) -> 24.846
A14: Hancock Roy Hill (1 Hub) | B14: Baltic C5 x 1.00 | C14: =Assumptions!$H10*IF(LEFT($B14,9)="Baltic C5",C$4,C$5) -> 10.4 | D14: =Assumptions!$H10*IF(LEFT($B14,9)="Baltic C5",D$4,D$5) -> 9.1 | E14: =Assumptions!$H10*IF(LEFT($B14,9)="Baltic C5",E$4,E$5) -> 7.8 | F14: =Assumptions!$H10*IF(LEFT($B14,9)="Baltic C5",F$4,F$5) -> 8.8 | G14: =Assumptions!$H10*IF(LEFT($B14,9)="Baltic C5",G$4,G$5) -> 8.1 | H14: =Assumptions!$H10*IF(LEFT($B14,9)="Baltic C5",H$4,H$5) -> 4.9 | I14: =Assumptions!$H10*IF(LEFT($B14,9)="Baltic C5",I$4,I$5) -> 4.5 | J14: =Assumptions!$H10*IF(LEFT($B14,9)="Baltic C5",J$4,J$5) -> 6.8 | ... AB14: =Assumptions!$H10*IF(LEFT($B14,9)="Baltic C5",AB$4,AB$5) -> 11
A15: MinRes Onslow Iron (1 Hub) | B15: Baltic C5 x 1.03 | C15: =Assumptions!$H11*IF(LEFT($B15,9)="Baltic C5",C$4,C$5) -> 10.712 | D15: =Assumptions!$H11*IF(LEFT($B15,9)="Baltic C5",D$4,D$5) -> 9.373 | E15: =Assumptions!$H11*IF(LEFT($B15,9)="Baltic C5",E$4,E$5) -> 8.034 | F15: =Assumptions!$H11*IF(LEFT($B15,9)="Baltic C5",F$4,F$5) -> 9.064 | G15: =Assumptions!$H11*IF(LEFT($B15,9)="Baltic C5",G$4,G$5) -> 8.343 | H15: =Assumptions!$H11*IF(LEFT($B15,9)="Baltic C5",H$4,H$5) -> 5.047 | I15: =Assumptions!$H11*IF(LEFT($B15,9)="Baltic C5",I$4,I$5) -> 4.635 | J15: =Assumptions!$H11*IF(LEFT($B15,9)="Baltic C5",J$4,J$5) -> 7.004 | ... AB15: =Assumptions!$H11*IF(LEFT($B15,9)="Baltic C5",AB$4,AB$5) -> 11.33
A16: MinRes Pilbara Hub (1 Hub) | B16: Baltic C5 x 1.00 | C16: =Assumptions!$H12*IF(LEFT($B16,9)="Baltic C5",C$4,C$5) -> 10.4 | D16: =Assumptions!$H12*IF(LEFT($B16,9)="Baltic C5",D$4,D$5) -> 9.1 | E16: =Assumptions!$H12*IF(LEFT($B16,9)="Baltic C5",E$4,E$5) -> 7.8 | F16: =Assumptions!$H12*IF(LEFT($B16,9)="Baltic C5",F$4,F$5) -> 8.8 | G16: =Assumptions!$H12*IF(LEFT($B16,9)="Baltic C5",G$4,G$5) -> 8.1 | H16: =Assumptions!$H12*IF(LEFT($B16,9)="Baltic C5",H$4,H$5) -> 4.9 | I16: =Assumptions!$H12*IF(LEFT($B16,9)="Baltic C5",I$4,I$5) -> 4.5 | J16: =Assumptions!$H12*IF(LEFT($B16,9)="Baltic C5",J$4,J$5) -> 6.8 | ... AB16: =Assumptions!$H12*IF(LEFT($B16,9)="Baltic C5",AB$4,AB$5) -> 11
A17: Hancock Atlas Iron (3 Hubs) | B17: Baltic C5 x 1.00 | C17: =Assumptions!$H13*IF(LEFT($B17,9)="Baltic C5",C$4,C$5) -> 10.4 | D17: =Assumptions!$H13*IF(LEFT($B17,9)="Baltic C5",D$4,D$5) -> 9.1 | E17: =Assumptions!$H13*IF(LEFT($B17,9)="Baltic C5",E$4,E$5) -> 7.8 | F17: =Assumptions!$H13*IF(LEFT($B17,9)="Baltic C5",F$4,F$5) -> 8.8 | G17: =Assumptions!$H13*IF(LEFT($B17,9)="Baltic C5",G$4,G$5) -> 8.1 | H17: =Assumptions!$H13*IF(LEFT($B17,9)="Baltic C5",H$4,H$5) -> 4.9 | I17: =Assumptions!$H13*IF(LEFT($B17,9)="Baltic C5",I$4,I$5) -> 4.5 | J17: =Assumptions!$H13*IF(LEFT($B17,9)="Baltic C5",J$4,J$5) -> 6.8 | ... AB17: =Assumptions!$H13*IF(LEFT($B17,9)="Baltic C5",AB$4,AB$5) -> 11
A18: CITIC Sino Iron (1 Hub) | B18: Baltic C5 x 1.00 | C18: =Assumptions!$H14*IF(LEFT($B18,9)="Baltic C5",C$4,C$5) -> 10.4 | D18: =Assumptions!$H14*IF(LEFT($B18,9)="Baltic C5",D$4,D$5) -> 9.1 | E18: =Assumptions!$H14*IF(LEFT($B18,9)="Baltic C5",E$4,E$5) -> 7.8 | F18: =Assumptions!$H14*IF(LEFT($B18,9)="Baltic C5",F$4,F$5) -> 8.8 | G18: =Assumptions!$H14*IF(LEFT($B18,9)="Baltic C5",G$4,G$5) -> 8.1 | H18: =Assumptions!$H14*IF(LEFT($B18,9)="Baltic C5",H$4,H$5) -> 4.9 | I18: =Assumptions!$H14*IF(LEFT($B18,9)="Baltic C5",I$4,I$5) -> 4.5 | J18: =Assumptions!$H14*IF(LEFT($B18,9)="Baltic C5",J$4,J$5) -> 6.8 | ... AB18: =Assumptions!$H14*IF(LEFT($B18,9)="Baltic C5",AB$4,AB$5) -> 11
... A77: Opaque Producer Supply | B77: Baltic C5 x 0.60 + Baltic C5 x 0.40 | C77: =Assumptions!$H73*IF(LEFT($B77,9)="Baltic C5",C$4,C$5) -> 10.4 | D77: =Assumptions!$H73*IF(LEFT($B77,9)="Baltic C5",D$4,D$5) -> 9.1 | E77: =Assumptions!$H73*IF(LEFT($B77,9)="Baltic C5",E$4,E$5) -> 7.8 | F77: =Assumptions!$H73*IF(LEFT($B77,9)="Baltic C5",F$4,F$5) -> 8.8 | G77: =Assumptions!$H73*IF(LEFT($B77,9)="Baltic C5",G$4,G$5) -> 8.1 | H77: =Assumptions!$H73*IF(LEFT($B77,9)="Baltic C5",H$4,H$5) -> 4.9 | I77: =Assumptions!$H73*IF(LEFT($B77,9)="Baltic C5",I$4,I$5) -> 4.5 | J77: =Assumptions!$H73*IF(LEFT($B77,9)="Baltic C5",J$4,J$5) -> 6.8 | ... AB77: =Assumptions!$H73*IF(LEFT($B77,9)="Baltic C5",AB$4,AB$5) -> 11

Sheet Final CFR cost
A1: Qingdao CFR Cash Cost – Benchmark Grade Equivalent
A2: CFR Cash Break-Even Cost at Qingdao USD dtm | Royalty-Adjusted FOB Cost Plus Freight
A3: Asset | C3: 2010 | D3: 2011 | E3: 2012 | F3: 2013 | G3: 2014 | H3: 2015 | I3: 2016 | J3: 2017 | K3: 2018 | L3: 2019 | M3: 2020 | N3: 2021 | O3: 2022 | P3: 2023 | Q3: 2024 | R3: 2025 | S3: 2026 | T3: 2027 | U3: 2028 | V3: 2029 | W3: 2030 | X3: 2031 | Y3: 2032 | Z3: 2033 | AA3: 2034 | AB3: 2035
A4: BHP WAIO (5 Hubs) | C4: =IF('Seaborne Supply'!C3=0,0,('FOB Cost'!C3/(1-Assumptions!$E3/100)+'Freight to Qingdao'!C7)/(1-Assumptions!$D3/100)) -> 36.756757 | D4: =IF('Seaborne Supply'!D3=0,0,('FOB Cost'!D3/(1-Assumptions!$E3/100)+'Freight to Qingdao'!D7)/(1-Assumptions!$D3/100)) -> 42.91485 | E4: =IF('Seaborne Supply'!E3=0,0,('FOB Cost'!E3/(1-Assumptions!$E3/100)+'Freight to Qingdao'!E7)/(1-Assumptions!$D3/100)) -> 43.144435 | F4: =IF('Seaborne Supply'!F3=0,0,('FOB Cost'!F3/(1-Assumptions!$E3/100)+'Freight to Qingdao'!F7)/(1-Assumptions!$D3/100)) -> 43.638477 | G4: =IF('Seaborne Supply'!G3=0,0,('FOB Cost'!G3/(1-Assumptions!$E3/100)+'Freight to Qingdao'!G7)/(1-Assumptions!$D3/100)) -> 40.095902 | H4: =IF('Seaborne Supply'!H3=0,0,('FOB Cost'!H3/(1-Assumptions!$E3/100)+'Freight to Qingdao'!H7)/(1-Assumptions!$D3/100)) -> 27.006684 | I4: =IF('Seaborne Supply'!I3=0,0,('FOB Cost'!I3/(1-Assumptions!$E3/100)+'Freight to Qingdao'!I7)/(1-Assumptions!$D3/100)) -> 22.391747 | J4: =IF('Seaborne Supply'!J3=0,0,('FOB Cost'!J3/(1-Assumptions!$E3/100)+'Freight to Qingdao'!J7)/(1-Assumptions!$D3/100)) -> 24.283638 | ... AB4: =IF('Seaborne Supply'!AB3=0,0,('FOB Cost'!AB3/(1-Assumptions!$E3/100)+'Freight to Qingdao'!AB7)/(1-Assumptions!$D3/100)) -> 34.263296
A5: Rio Tinto Pilbara (8 Hubs) | C5: =IF('Seaborne Supply'!C4=0,0,('FOB Cost'!C4/(1-Assumptions!$E4/100)+'Freight to Qingdao'!C8)/(1-Assumptions!$D4/100)) -> 35.013078 | D5: =IF('Seaborne Supply'!D4=0,0,('FOB Cost'!D4/(1-Assumptions!$E4/100)+'Freight to Qingdao'!D8)/(1-Assumptions!$D4/100)) -> 37.567568 | E5: =IF('Seaborne Supply'!E4=0,0,('FOB Cost'!E4/(1-Assumptions!$E4/100)+'Freight to Qingdao'!E8)/(1-Assumptions!$D4/100)) -> 33.728567 | F5: =IF('Seaborne Supply'!F4=0,0,('FOB Cost'!F4/(1-Assumptions!$E4/100)+'Freight to Qingdao'!F8)/(1-Assumptions!$D4/100)) -> 32.943912 | G5: =IF('Seaborne Supply'!G4=0,0,('FOB Cost'!G4/(1-Assumptions!$E4/100)+'Freight to Qingdao'!G8)/(1-Assumptions!$D4/100)) -> 31.377507 | H5: =IF('Seaborne Supply'!H4=0,0,('FOB Cost'!H4/(1-Assumptions!$E4/100)+'Freight to Qingdao'!H8)/(1-Assumptions!$D4/100)) -> 22.589364 | I5: =IF('Seaborne Supply'!I4=0,0,('FOB Cost'!I4/(1-Assumptions!$E4/100)+'Freight to Qingdao'!I8)/(1-Assumptions!$D4/100)) -> 20.764313 | J5: =IF('Seaborne Supply'!J4=0,0,('FOB Cost'!J4/(1-Assumptions!$E4/100)+'Freight to Qingdao'!J8)/(1-Assumptions!$D4/100)) -> 22.888695 | ... AB5: =IF('Seaborne Supply'!AB4=0,0,('FOB Cost'!AB4/(1-Assumptions!$E4/100)+'Freight to Qingdao'!AB8)/(1-Assumptions!$D4/100)) -> 39.494333
A6: Fortescue Hematite (3 Hubs) | C6: =IF('Seaborne Supply'!C5=0,0,('FOB Cost'!C5/(1-Assumptions!$E5/100)+'Freight to Qingdao'!C9)/(1-Assumptions!$D5/100)) -> 47.992911 | D6: =IF('Seaborne Supply'!D5=0,0,('FOB Cost'!D5/(1-Assumptions!$E5/100)+'Freight to Qingdao'!D9)/(1-Assumptions!$D5/100)) -> 61.931768 | E6: =IF('Seaborne Supply'!E5=0,0,('FOB Cost'!E5/(1-Assumptions!$E5/100)+'Freight to Qingdao'!E9)/(1-Assumptions!$D5/100)) -> 65.23704 | F6: =IF('Seaborne Supply'!F5=0,0,('FOB Cost'!F5/(1-Assumptions!$E5/100)+'Freight to Qingdao'!F9)/(1-Assumptions!$D5/100)) -> 61.603899 | G6: =IF('Seaborne Supply'!G5=0,0,('FOB Cost'!G5/(1-Assumptions!$E5/100)+'Freight to Qingdao'!G9)/(1-Assumptions!$D5/100)) -> 49.023778 | H6: =IF('Seaborne Supply'!H5=0,0,('FOB Cost'!H5/(1-Assumptions!$E5/100)+'Freight to Qingdao'!H9)/(1-Assumptions!$D5/100)) -> 37.255944 | I6: =IF('Seaborne Supply'!I5=0,0,('FOB Cost'!I5/(1-Assumptions!$E5/100)+'Freight to Qingdao'!I9)/(1-Assumptions!$D5/100)) -> 23.148722 | J6: =IF('Seaborne Supply'!J5=0,0,('FOB Cost'!J5/(1-Assumptions!$E5/100)+'Freight to Qingdao'!J9)/(1-Assumptions!$D5/100)) -> 22.578644 | ... AB6: =IF('Seaborne Supply'!AB5=0,0,('FOB Cost'!AB5/(1-Assumptions!$E5/100)+'Freight to Qingdao'!AB9)/(1-Assumptions!$D5/100)) -> 36.006498
A7: Fortescue Iron Bridge Magnetite Project (1 Hub) | C7: =IF('Seaborne Supply'!C6=0,0,('FOB Cost'!C6/(1-Assumptions!$E6/100)+'Freight to Qingdao'!C10)/(1-Assumptions!$D6/100)) -> 0 | D7: =IF('Seaborne Supply'!D6=0,0,('FOB Cost'!D6/(1-Assumptions!$E6/100)+'Freight to Qingdao'!D10)/(1-Assumptions!$D6/100)) -> 0 | E7: =IF('Seaborne Supply'!E6=0,0,('FOB Cost'!E6/(1-Assumptions!$E6/100)+'Freight to Qingdao'!E10)/(1-Assumptions!$D6/100)) -> 0 | F7: =IF('Seaborne Supply'!F6=0,0,('FOB Cost'!F6/(1-Assumptions!$E6/100)+'Freight to Qingdao'!F10)/(1-Assumptions!$D6/100)) -> 0 | G7: =IF('Seaborne Supply'!G6=0,0,('FOB Cost'!G6/(1-Assumptions!$E6/100)+'Freight to Qingdao'!G10)/(1-Assumptions!$D6/100)) -> 0 | H7: =IF('Seaborne Supply'!H6=0,0,('FOB Cost'!H6/(1-Assumptions!$E6/100)+'Freight to Qingdao'!H10)/(1-Assumptions!$D6/100)) -> 0 | I7: =IF('Seaborne Supply'!I6=0,0,('FOB Cost'!I6/(1-Assumptions!$E6/100)+'Freight to Qingdao'!I10)/(1-Assumptions!$D6/100)) -> 0 | J7: =IF('Seaborne Supply'!J6=0,0,('FOB Cost'!J6/(1-Assumptions!$E6/100)+'Freight to Qingdao'!J10)/(1-Assumptions!$D6/100)) -> 0 | ... AB7: =IF('Seaborne Supply'!AB6=0,0,('FOB Cost'!AB6/(1-Assumptions!$E6/100)+'Freight to Qingdao'!AB10)/(1-Assumptions!$D6/100)) -> 74.320416
A8: Vale Northern System (3 Hubs) | C8: =IF('Seaborne Supply'!C7=0,0,('FOB Cost'!C7/(1-Assumptions!$E7/100)+'Freight to Qingdao'!C11)/(1-Assumptions!$D7/100)) -> 51.477857 | D8: =IF('Seaborne Supply'!D7=0,0,('FOB Cost'!D7/(1-Assumptions!$E7/100)+'Freight to Qingdao'!D11)/(1-Assumptions!$D7/100)) -> 50.016248 | E8: =IF('Seaborne Supply'!E7=0,0,('FOB Cost'!E7/(1-Assumptions!$E7/100)+'Freight to Qingdao'!E11)/(1-Assumptions!$D7/100)) -> 44.549014 | F8: =IF('Seaborne Supply'!F7=0,0,('FOB Cost'!F7/(1-Assumptions!$E7/100)+'Freight to Qingdao'!F11)/(1-Assumptions!$D7/100)) -> 43.92091 | G8: =IF('Seaborne Supply'!G7=0,0,('FOB Cost'!G7/(1-Assumptions!$E7/100)+'Freight to Qingdao'!G11)/(1-Assumptions!$D7/100)) -> 43.90511 | H8: =IF('Seaborne Supply'!H7=0,0,('FOB Cost'!H7/(1-Assumptions!$E7/100)+'Freight to Qingdao'!H11)/(1-Assumptions!$D7/100)) -> 27.135634 | I8: =IF('Seaborne Supply'!I7=0,0,('FOB Cost'!I7/(1-Assumptions!$E7/100)+'Freight to Qingdao'!I11)/(1-Assumptions!$D7/100)) -> 22.250807 | J8: =IF('Seaborne Supply'!J7=0,0,('FOB Cost'!J7/(1-Assumptions!$E7/100)+'Freight to Qingdao'!J11)/(1-Assumptions!$D7/100)) -> 30.399641 | ... AB8: =IF('Seaborne Supply'!AB7=0,0,('FOB Cost'!AB7/(1-Assumptions!$E7/100)+'Freight to Qingdao'!AB11)/(1-Assumptions!$D7/100)) -> 46.945002
A9: Vale Southeastern System (3 Hubs) | C9: =IF('Seaborne Supply'!C8=0,0,('FOB Cost'!C8/(1-Assumptions!$E8/100)+'Freight to Qingdao'!C12)/(1-Assumptions!$D8/100)) -> 56.492604 | D9: =IF('Seaborne Supply'!D8=0,0,('FOB Cost'!D8/(1-Assumptions!$E8/100)+'Freight to Qingdao'!D12)/(1-Assumptions!$D8/100)) -> 55.832586 | E9: =IF('Seaborne Supply'!E8=0,0,('FOB Cost'!E8/(1-Assumptions!$E8/100)+'Freight to Qingdao'!E12)/(1-Assumptions!$D8/100)) -> 49.987674 | F9: =IF('Seaborne Supply'!F8=0,0,('FOB Cost'!F8/(1-Assumptions!$E8/100)+'Freight to Qingdao'!F12)/(1-Assumptions!$D8/100)) -> 49.268265 | G9: =IF('Seaborne Supply'!G8=0,0,('FOB Cost'!G8/(1-Assumptions!$E8/100)+'Freight to Qingdao'!G12)/(1-Assumptions!$D8/100)) -> 49.285074 | H9: =IF('Seaborne Supply'!H8=0,0,('FOB Cost'!H8/(1-Assumptions!$E8/100)+'Freight to Qingdao'!H12)/(1-Assumptions!$D8/100)) -> 31.783953 | I9: =IF('Seaborne Supply'!I8=0,0,('FOB Cost'!I8/(1-Assumptions!$E8/100)+'Freight to Qingdao'!I12)/(1-Assumptions!$D8/100)) -> 27.820484 | J9: =IF('Seaborne Supply'!J8=0,0,('FOB Cost'!J8/(1-Assumptions!$E8/100)+'Freight to Qingdao'!J12)/(1-Assumptions!$D8/100)) -> 35.571493 | ... AB9: =IF('Seaborne Supply'!AB8=0,0,('FOB Cost'!AB8/(1-Assumptions!$E8/100)+'Freight to Qingdao'!AB12)/(1-Assumptions!$D8/100)) -> 57.106679
A10: Vale Southern System (2 Hubs) | C10: =IF('Seaborne Supply'!C9=0,0,('FOB Cost'!C9/(1-Assumptions!$E9/100)+'Freight to Qingdao'!C13)/(1-Assumptions!$D9/100)) -> 53.144206 | D10: =IF('Seaborne Supply'!D9=0,0,('FOB Cost'!D9/(1-Assumptions!$E9/100)+'Freight to Qingdao'!D13)/(1-Assumptions!$D9/100)) -> 51.876796 | E10: =IF('Seaborne Supply'!E9=0,0,('FOB Cost'!E9/(1-Assumptions!$E9/100)+'Freight to Qingdao'!E13)/(1-Assumptions!$D9/100)) -> 46.532691 | F10: =IF('Seaborne Supply'!F9=0,0,('FOB Cost'!F9/(1-Assumptions!$E9/100)+'Freight to Qingdao'!F13)/(1-Assumptions!$D9/100)) -> 45.824652 | G10: =IF('Seaborne Supply'!G9=0,0,('FOB Cost'!G9/(1-Assumptions!$E9/100)+'Freight to Qingdao'!G13)/(1-Assumptions!$D9/100)) -> 45.836088 | H10: =IF('Seaborne Supply'!H9=0,0,('FOB Cost'!H9/(1-Assumptions!$E9/100)+'Freight to Qingdao'!H13)/(1-Assumptions!$D9/100)) -> 26.446555 | I10: =IF('Seaborne Supply'!I9=0,0,('FOB Cost'!I9/(1-Assumptions!$E9/100)+'Freight to Qingdao'!I13)/(1-Assumptions!$D9/100)) -> 24.691871 | J10: =IF('Seaborne Supply'!J9=0,0,('FOB Cost'!J9/(1-Assumptions!$E9/100)+'Freight to Qingdao'!J13)/(1-Assumptions!$D9/100)) -> 33.11525 | ... AB10: =IF('Seaborne Supply'!AB9=0,0,('FOB Cost'!AB9/(1-Assumptions!$E9/100)+'Freight to Qingdao'!AB13)/(1-Assumptions!$D9/100)) -> 55.096186
